<?xml version="1.0" encoding="UTF-8"?>
<testng-results retried="2" ignored="2" total="6" passed="1" failed="1" skipped="0">
  <reporter-output>
  </reporter-output>
  <suite started-at="2023-09-13T16:02:08 IST" name="All Test Suite" finished-at="2023-09-13T16:02:38 IST" duration-ms="30534">
    <groups>
    </groups>
    <test started-at="2023-09-13T16:02:08 IST" name="C:/Users/nayan/IdeaProjects/CromaProject" finished-at="2023-09-13T16:02:38 IST" duration-ms="30534">
      <class name="testcases.HomeTest">
        <test-method is-config="true" signature="beforeMethod()[pri:0, instance:testcases.HomeTest@402e37bc]" started-at="2023-09-13T16:02:08 IST" name="beforeMethod" finished-at="2023-09-13T16:02:12 IST" duration-ms="4346" status="PASS">
          <reporter-output>
          </reporter-output>
        </test-method> <!-- beforeMethod -->
        <test-method signature="verifyFunctionalityOfLink()[pri:1, instance:testcases.HomeTest@402e37bc]" started-at="2023-09-13T16:02:12 IST" name="verifyFunctionalityOfLink" description="verifying the functionality of Link and coming back to Parent window" finished-at="2023-09-13T16:02:22 IST" duration-ms="9631" status="PASS">
          <reporter-output>
          </reporter-output>
        </test-method> <!-- verifyFunctionalityOfLink -->
        <test-method is-config="true" signature="tearDown()[pri:0, instance:testcases.HomeTest@402e37bc]" started-at="2023-09-13T16:02:22 IST" name="tearDown" finished-at="2023-09-13T16:02:22 IST" duration-ms="213" status="PASS">
          <reporter-output>
          </reporter-output>
        </test-method> <!-- tearDown -->
        <test-method is-config="true" signature="beforeMethod()[pri:0, instance:testcases.HomeTest@402e37bc]" started-at="2023-09-13T16:02:22 IST" name="beforeMethod" finished-at="2023-09-13T16:02:26 IST" duration-ms="3795" status="PASS">
          <reporter-output>
          </reporter-output>
        </test-method> <!-- beforeMethod -->
        <test-method retried="true" signature="failedTestCases()[pri:2, instance:testcases.HomeTest@402e37bc]" started-at="2023-09-13T16:02:26 IST" name="failedTestCases" description="Method to Run Only Failed Test Cases" finished-at="2023-09-13T16:02:26 IST" duration-ms="4" status="SKIP">
          <exception class="java.lang.AssertionError">
            <message>
              <![CDATA[expected [false] but found [true]]]>
            </message>
            <full-stacktrace>
              <![CDATA[java.lang.AssertionError: expected [false] but found [true]
at org.testng.Assert.fail(Assert.java:111)
at org.testng.Assert.failNotEquals(Assert.java:1578)
at org.testng.Assert.assertFalse(Assert.java:79)
at org.testng.Assert.assertFalse(Assert.java:89)
at testcases.HomeTest.failedTestCases(HomeTest.java:47)
at java.base/jdk.internal.reflect.DirectMethodHandleAccessor.invoke(DirectMethodHandleAccessor.java:104)
at java.base/java.lang.reflect.Method.invoke(Method.java:578)
at org.testng.internal.invokers.MethodInvocationHelper.invokeMethod(MethodInvocationHelper.java:139)
at org.testng.internal.invokers.TestInvoker.invokeMethod(TestInvoker.java:664)
at org.testng.internal.invokers.TestInvoker.invokeTestMethod(TestInvoker.java:227)
at org.testng.internal.invokers.MethodRunner.runInSequence(MethodRunner.java:50)
at org.testng.internal.invokers.TestInvoker$MethodInvocationAgent.invoke(TestInvoker.java:957)
at org.testng.internal.invokers.TestInvoker.invokeTestMethods(TestInvoker.java:200)
at org.testng.internal.invokers.TestMethodWorker.invokeTestMethods(TestMethodWorker.java:148)
at org.testng.internal.invokers.TestMethodWorker.run(TestMethodWorker.java:128)
at java.base/java.util.ArrayList.forEach(ArrayList.java:1511)
at org.testng.TestRunner.privateRun(TestRunner.java:848)
at org.testng.TestRunner.run(TestRunner.java:621)
at org.testng.SuiteRunner.runTest(SuiteRunner.java:443)
at org.testng.SuiteRunner.runSequentially(SuiteRunner.java:437)
at org.testng.SuiteRunner.privateRun(SuiteRunner.java:397)
at org.testng.SuiteRunner.run(SuiteRunner.java:336)
at org.testng.SuiteRunnerWorker.runSuite(SuiteRunnerWorker.java:52)
at org.testng.SuiteRunnerWorker.run(SuiteRunnerWorker.java:95)
at org.testng.TestNG.runSuitesSequentially(TestNG.java:1280)
at org.testng.TestNG.runSuitesLocally(TestNG.java:1200)
at org.testng.TestNG.runSuites(TestNG.java:1114)
at org.testng.TestNG.run(TestNG.java:1082)
at com.intellij.rt.testng.IDEARemoteTestNG.run(IDEARemoteTestNG.java:66)
at com.intellij.rt.testng.RemoteTestNGStarter.main(RemoteTestNGStarter.java:105)
]]>
            </full-stacktrace>
          </exception> <!-- java.lang.AssertionError -->
          <reporter-output>
          </reporter-output>
        </test-method> <!-- failedTestCases -->
        <test-method is-config="true" signature="tearDown()[pri:0, instance:testcases.HomeTest@402e37bc]" started-at="2023-09-13T16:02:26 IST" name="tearDown" finished-at="2023-09-13T16:02:26 IST" duration-ms="128" status="PASS">
          <reporter-output>
          </reporter-output>
        </test-method> <!-- tearDown -->
        <test-method is-config="true" signature="beforeMethod()[pri:0, instance:testcases.HomeTest@402e37bc]" started-at="2023-09-13T16:02:26 IST" name="beforeMethod" finished-at="2023-09-13T16:02:30 IST" duration-ms="3908" status="PASS">
          <reporter-output>
          </reporter-output>
        </test-method> <!-- beforeMethod -->
        <test-method retried="true" signature="failedTestCases()[pri:2, instance:testcases.HomeTest@402e37bc]" started-at="2023-09-13T16:02:30 IST" name="failedTestCases" description="Method to Run Only Failed Test Cases" finished-at="2023-09-13T16:02:30 IST" duration-ms="1" status="SKIP">
          <exception class="java.lang.AssertionError">
            <message>
              <![CDATA[expected [false] but found [true]]]>
            </message>
            <full-stacktrace>
              <![CDATA[java.lang.AssertionError: expected [false] but found [true]
at org.testng.Assert.fail(Assert.java:111)
at org.testng.Assert.failNotEquals(Assert.java:1578)
at org.testng.Assert.assertFalse(Assert.java:79)
at org.testng.Assert.assertFalse(Assert.java:89)
at testcases.HomeTest.failedTestCases(HomeTest.java:47)
at java.base/jdk.internal.reflect.DirectMethodHandleAccessor.invoke(DirectMethodHandleAccessor.java:104)
at java.base/java.lang.reflect.Method.invoke(Method.java:578)
at org.testng.internal.invokers.MethodInvocationHelper.invokeMethod(MethodInvocationHelper.java:139)
at org.testng.internal.invokers.TestInvoker.invokeMethod(TestInvoker.java:664)
at org.testng.internal.invokers.TestInvoker.retryFailed(TestInvoker.java:248)
at org.testng.internal.invokers.MethodRunner.runInSequence(MethodRunner.java:62)
at org.testng.internal.invokers.TestInvoker$MethodInvocationAgent.invoke(TestInvoker.java:957)
at org.testng.internal.invokers.TestInvoker.invokeTestMethods(TestInvoker.java:200)
at org.testng.internal.invokers.TestMethodWorker.invokeTestMethods(TestMethodWorker.java:148)
at org.testng.internal.invokers.TestMethodWorker.run(TestMethodWorker.java:128)
at java.base/java.util.ArrayList.forEach(ArrayList.java:1511)
at org.testng.TestRunner.privateRun(TestRunner.java:848)
at org.testng.TestRunner.run(TestRunner.java:621)
at org.testng.SuiteRunner.runTest(SuiteRunner.java:443)
at org.testng.SuiteRunner.runSequentially(SuiteRunner.java:437)
at org.testng.SuiteRunner.privateRun(SuiteRunner.java:397)
at org.testng.SuiteRunner.run(SuiteRunner.java:336)
at org.testng.SuiteRunnerWorker.runSuite(SuiteRunnerWorker.java:52)
at org.testng.SuiteRunnerWorker.run(SuiteRunnerWorker.java:95)
at org.testng.TestNG.runSuitesSequentially(TestNG.java:1280)
at org.testng.TestNG.runSuitesLocally(TestNG.java:1200)
at org.testng.TestNG.runSuites(TestNG.java:1114)
at org.testng.TestNG.run(TestNG.java:1082)
at com.intellij.rt.testng.IDEARemoteTestNG.run(IDEARemoteTestNG.java:66)
at com.intellij.rt.testng.RemoteTestNGStarter.main(RemoteTestNGStarter.java:105)
]]>
            </full-stacktrace>
          </exception> <!-- java.lang.AssertionError -->
          <reporter-output>
          </reporter-output>
        </test-method> <!-- failedTestCases -->
        <test-method is-config="true" signature="tearDown()[pri:0, instance:testcases.HomeTest@402e37bc]" started-at="2023-09-13T16:02:30 IST" name="tearDown" finished-at="2023-09-13T16:02:30 IST" duration-ms="141" status="PASS">
          <reporter-output>
          </reporter-output>
        </test-method> <!-- tearDown -->
        <test-method is-config="true" signature="beforeMethod()[pri:0, instance:testcases.HomeTest@402e37bc]" started-at="2023-09-13T16:02:30 IST" name="beforeMethod" finished-at="2023-09-13T16:02:38 IST" duration-ms="8220" status="PASS">
          <reporter-output>
          </reporter-output>
        </test-method> <!-- beforeMethod -->
        <test-method signature="failedTestCases()[pri:2, instance:testcases.HomeTest@402e37bc]" started-at="2023-09-13T16:02:38 IST" name="failedTestCases" description="Method to Run Only Failed Test Cases" finished-at="2023-09-13T16:02:38 IST" duration-ms="1" status="FAIL">
          <exception class="java.lang.AssertionError">
            <message>
              <![CDATA[expected [false] but found [true]]]>
            </message>
            <full-stacktrace>
              <![CDATA[java.lang.AssertionError: expected [false] but found [true]
at org.testng.Assert.fail(Assert.java:111)
at org.testng.Assert.failNotEquals(Assert.java:1578)
at org.testng.Assert.assertFalse(Assert.java:79)
at org.testng.Assert.assertFalse(Assert.java:89)
at testcases.HomeTest.failedTestCases(HomeTest.java:47)
at java.base/jdk.internal.reflect.DirectMethodHandleAccessor.invoke(DirectMethodHandleAccessor.java:104)
at java.base/java.lang.reflect.Method.invoke(Method.java:578)
at org.testng.internal.invokers.MethodInvocationHelper.invokeMethod(MethodInvocationHelper.java:139)
at org.testng.internal.invokers.TestInvoker.invokeMethod(TestInvoker.java:664)
at org.testng.internal.invokers.TestInvoker.retryFailed(TestInvoker.java:248)
at org.testng.internal.invokers.MethodRunner.runInSequence(MethodRunner.java:62)
at org.testng.internal.invokers.TestInvoker$MethodInvocationAgent.invoke(TestInvoker.java:957)
at org.testng.internal.invokers.TestInvoker.invokeTestMethods(TestInvoker.java:200)
at org.testng.internal.invokers.TestMethodWorker.invokeTestMethods(TestMethodWorker.java:148)
at org.testng.internal.invokers.TestMethodWorker.run(TestMethodWorker.java:128)
at java.base/java.util.ArrayList.forEach(ArrayList.java:1511)
at org.testng.TestRunner.privateRun(TestRunner.java:848)
at org.testng.TestRunner.run(TestRunner.java:621)
at org.testng.SuiteRunner.runTest(SuiteRunner.java:443)
at org.testng.SuiteRunner.runSequentially(SuiteRunner.java:437)
at org.testng.SuiteRunner.privateRun(SuiteRunner.java:397)
at org.testng.SuiteRunner.run(SuiteRunner.java:336)
at org.testng.SuiteRunnerWorker.runSuite(SuiteRunnerWorker.java:52)
at org.testng.SuiteRunnerWorker.run(SuiteRunnerWorker.java:95)
at org.testng.TestNG.runSuitesSequentially(TestNG.java:1280)
at org.testng.TestNG.runSuitesLocally(TestNG.java:1200)
at org.testng.TestNG.runSuites(TestNG.java:1114)
at org.testng.TestNG.run(TestNG.java:1082)
at com.intellij.rt.testng.IDEARemoteTestNG.run(IDEARemoteTestNG.java:66)
at com.intellij.rt.testng.RemoteTestNGStarter.main(RemoteTestNGStarter.java:105)
]]>
            </full-stacktrace>
          </exception> <!-- java.lang.AssertionError -->
          <reporter-output>
          </reporter-output>
        </test-method> <!-- failedTestCases -->
        <test-method is-config="true" signature="tearDown()[pri:0, instance:testcases.HomeTest@402e37bc]" started-at="2023-09-13T16:02:38 IST" name="tearDown" finished-at="2023-09-13T16:02:38 IST" duration-ms="110" status="PASS">
          <reporter-output>
          </reporter-output>
        </test-method> <!-- tearDown -->
      </class> <!-- testcases.HomeTest -->
    </test> <!-- C:/Users/nayan/IdeaProjects/CromaProject -->
  </suite> <!-- All Test Suite -->
</testng-results>
